<?xml version="1.0"?>
<robot name="go2_like">
  <link name="base_link">
    <inertial>
      <origin xyz="0 0 0" rpy="0 0 0"/>
      <mass value="5.0"/>
      <inertia ixx="0.2" iyy="0.2" izz="0.2" ixy="0" ixz="0" iyz="0"/>
    </inertial>
    <!-- Main body - silver gray -->
    <visual>
      <origin xyz="0 0 0" rpy="0 0 0"/>
      <geometry>
        <box size="0.4 0.25 0.12"/>
      </geometry>
      <material name="silver">
        <color rgba="0.6 0.65 0.7 1"/>
      </material>
    </visual>
    <!-- Top section - darker gray -->
    <visual>
      <origin xyz="0 0 0.06" rpy="0 0 0"/>
      <geometry>
        <box size="0.35 0.22 0.02"/>
      </geometry>
      <material name="dark_silver">
        <color rgba="0.4 0.45 0.5 1"/>
      </material>
    </visual>
    <!-- Front head section -->
    <visual>
      <origin xyz="0.17 0 0.02" rpy="0 0 0"/>
      <geometry>
        <box size="0.08 0.18 0.08"/>
      </geometry>
      <material name="dark_silver">
        <color rgba="0.4 0.45 0.5 1"/>
      </material>
    </visual>
    <collision>
      <origin xyz="0 0 0" rpy="0 0 0"/>
      <geometry>
        <box size="0.4 0.25 0.12"/>
      </geometry>
    </collision>
  </link>

  <!-- Front Left Leg -->
  <link name="fl_hip_link">
    <inertial>
      <origin xyz="0 0 0" rpy="0 0 0"/>
      <mass value="0.2"/>
      <inertia ixx="0.001" iyy="0.001" izz="0.001" ixy="0" ixz="0" iyz="0"/>
    </inertial>
    <visual>
      <origin xyz="0 0 0" rpy="0 0 0"/>
      <geometry>
        <sphere radius="0.04"/>
      </geometry>
      <material name="silver">
        <color rgba="0.6 0.65 0.7 1"/>
      </material>
    </visual>
    <collision>
      <origin xyz="0 0 0" rpy="0 0 0"/>
      <geometry>
        <sphere radius="0.04"/>
      </geometry>
    </collision>
  </link>

  <link name="fl_thigh_link">
    <inertial>
      <origin xyz="0 0 -0.1" rpy="0 0 0"/>
      <mass value="0.3"/>
      <inertia ixx="0.002" iyy="0.002" izz="0.002" ixy="0" ixz="0" iyz="0"/>
    </inertial>
    <visual>
      <origin xyz="0 0 -0.1" rpy="0 0 0"/>
      <geometry>
        <cylinder radius="0.028" length="0.2"/>
      </geometry>
      <material name="silver">
        <color rgba="0.6 0.65 0.7 1"/>
      </material>
    </visual>
    <collision>
      <origin xyz="0 0 -0.1" rpy="0 0 0"/>
      <geometry>
        <cylinder radius="0.028" length="0.2"/>
      </geometry>
    </collision>
  </link>

  <link name="fl_shank_link">
    <inertial>
      <origin xyz="0 0 -0.1" rpy="0 0 0"/>
      <mass value="0.2"/>
      <inertia ixx="0.001" iyy="0.001" izz="0.001" ixy="0" ixz="0" iyz="0"/>
    </inertial>
    <!-- Upper shank - silver -->
    <visual>
      <origin xyz="0 0 -0.08" rpy="0 0 0"/>
      <geometry>
        <cylinder radius="0.022" length="0.16"/>
      </geometry>
      <material name="silver">
        <color rgba="0.6 0.65 0.7 1"/>
      </material>
    </visual>
    <!-- Foot pad - black rubber-like -->
    <visual>
      <origin xyz="0 0 -0.19" rpy="0 0 0"/>
      <geometry>
        <cylinder radius="0.032" length="0.04"/>
      </geometry>
      <material name="black_rubber">
        <color rgba="0.15 0.15 0.15 1"/>
      </material>
    </visual>
    <collision>
      <origin xyz="0 0 -0.1" rpy="0 0 0"/>
      <geometry>
        <cylinder radius="0.022" length="0.2"/>
      </geometry>
    </collision>
    <collision>
      <origin xyz="0 0 -0.19" rpy="0 0 0"/>
      <geometry>
        <cylinder radius="0.032" length="0.04"/>
      </geometry>
    </collision>
  </link>

  <!-- Front Right Leg -->
  <link name="fr_hip_link">
    <inertial>
      <origin xyz="0 0 0" rpy="0 0 0"/>
      <mass value="0.2"/>
      <inertia ixx="0.001" iyy="0.001" izz="0.001" ixy="0" ixz="0" iyz="0"/>
    </inertial>
    <visual>
      <origin xyz="0 0 0" rpy="0 0 0"/>
      <geometry>
        <sphere radius="0.04"/>
      </geometry>
      <material name="silver">
        <color rgba="0.6 0.65 0.7 1"/>
      </material>
    </visual>
    <collision>
      <origin xyz="0 0 0" rpy="0 0 0"/>
      <geometry>
        <sphere radius="0.04"/>
      </geometry>
    </collision>
  </link>

  <link name="fr_thigh_link">
    <inertial>
      <origin xyz="0 0 -0.1" rpy="0 0 0"/>
      <mass value="0.3"/>
      <inertia ixx="0.002" iyy="0.002" izz="0.002" ixy="0" ixz="0" iyz="0"/>
    </inertial>
    <visual>
      <origin xyz="0 0 -0.1" rpy="0 0 0"/>
      <geometry>
        <cylinder radius="0.028" length="0.2"/>
      </geometry>
      <material name="silver">
        <color rgba="0.6 0.65 0.7 1"/>
      </material>
    </visual>
    <collision>
      <origin xyz="0 0 -0.1" rpy="0 0 0"/>
      <geometry>
        <cylinder radius="0.028" length="0.2"/>
      </geometry>
    </collision>
  </link>

  <link name="fr_shank_link">
    <inertial>
      <origin xyz="0 0 -0.1" rpy="0 0 0"/>
      <mass value="0.2"/>
      <inertia ixx="0.001" iyy="0.001" izz="0.001" ixy="0" ixz="0" iyz="0"/>
    </inertial>
    <!-- Upper shank - silver -->
    <visual>
      <origin xyz="0 0 -0.08" rpy="0 0 0"/>
      <geometry>
        <cylinder radius="0.022" length="0.16"/>
      </geometry>
      <material name="silver">
        <color rgba="0.6 0.65 0.7 1"/>
      </material>
    </visual>
    <!-- Foot pad - black rubber-like -->
    <visual>
      <origin xyz="0 0 -0.19" rpy="0 0 0"/>
      <geometry>
        <cylinder radius="0.032" length="0.04"/>
      </geometry>
      <material name="black_rubber">
        <color rgba="0.15 0.15 0.15 1"/>
      </material>
    </visual>
    <collision>
      <origin xyz="0 0 -0.1" rpy="0 0 0"/>
      <geometry>
        <cylinder radius="0.022" length="0.2"/>
      </geometry>
    </collision>
    <collision>
      <origin xyz="0 0 -0.19" rpy="0 0 0"/>
      <geometry>
        <cylinder radius="0.032" length="0.04"/>
      </geometry>
    </collision>
  </link>

  <!-- Rear Left Leg -->
  <link name="rl_hip_link">
    <inertial>
      <origin xyz="0 0 0" rpy="0 0 0"/>
      <mass value="0.2"/>
      <inertia ixx="0.001" iyy="0.001" izz="0.001" ixy="0" ixz="0" iyz="0"/>
    </inertial>
    <visual>
      <origin xyz="0 0 0" rpy="0 0 0"/>
      <geometry>
        <sphere radius="0.04"/>
      </geometry>
      <material name="silver">
        <color rgba="0.6 0.65 0.7 1"/>
      </material>
    </visual>
    <collision>
      <origin xyz="0 0 0" rpy="0 0 0"/>
      <geometry>
        <sphere radius="0.04"/>
      </geometry>
    </collision>
  </link>

  <link name="rl_thigh_link">
    <inertial>
      <origin xyz="0 0 -0.1" rpy="0 0 0"/>
      <mass value="0.3"/>
      <inertia ixx="0.002" iyy="0.002" izz="0.002" ixy="0" ixz="0" iyz="0"/>
    </inertial>
    <visual>
      <origin xyz="0 0 -0.1" rpy="0 0 0"/>
      <geometry>
        <cylinder radius="0.028" length="0.2"/>
      </geometry>
      <material name="silver">
        <color rgba="0.6 0.65 0.7 1"/>
      </material>
    </visual>
    <collision>
      <origin xyz="0 0 -0.1" rpy="0 0 0"/>
      <geometry>
        <cylinder radius="0.028" length="0.2"/>
      </geometry>
    </collision>
  </link>

  <link name="rl_shank_link">
    <inertial>
      <origin xyz="0 0 -0.1" rpy="0 0 0"/>
      <mass value="0.2"/>
      <inertia ixx="0.001" iyy="0.001" izz="0.001" ixy="0" ixz="0" iyz="0"/>
    </inertial>
    <!-- Upper shank - silver -->
    <visual>
      <origin xyz="0 0 -0.08" rpy="0 0 0"/>
      <geometry>
        <cylinder radius="0.022" length="0.16"/>
      </geometry>
      <material name="silver">
        <color rgba="0.6 0.65 0.7 1"/>
      </material>
    </visual>
    <!-- Foot pad - black rubber-like -->
    <visual>
      <origin xyz="0 0 -0.19" rpy="0 0 0"/>
      <geometry>
        <cylinder radius="0.032" length="0.04"/>
      </geometry>
      <material name="black_rubber">
        <color rgba="0.15 0.15 0.15 1"/>
      </material>
    </visual>
    <collision>
      <origin xyz="0 0 -0.1" rpy="0 0 0"/>
      <geometry>
        <cylinder radius="0.022" length="0.2"/>
      </geometry>
    </collision>
    <collision>
      <origin xyz="0 0 -0.19" rpy="0 0 0"/>
      <geometry>
        <cylinder radius="0.032" length="0.04"/>
      </geometry>
    </collision>
  </link>

  <!-- Rear Right Leg -->
  <link name="rr_hip_link">
    <inertial>
      <origin xyz="0 0 0" rpy="0 0 0"/>
      <mass value="0.2"/>
      <inertia ixx="0.001" iyy="0.001" izz="0.001" ixy="0" ixz="0" iyz="0"/>
    </inertial>
    <visual>
      <origin xyz="0 0 0" rpy="0 0 0"/>
      <geometry>
        <sphere radius="0.04"/>
      </geometry>
      <material name="silver">
        <color rgba="0.6 0.65 0.7 1"/>
      </material>
    </visual>
    <collision>
      <origin xyz="0 0 0" rpy="0 0 0"/>
      <geometry>
        <sphere radius="0.04"/>
      </geometry>
    </collision>
  </link>

  <link name="rr_thigh_link">
    <inertial>
      <origin xyz="0 0 -0.1" rpy="0 0 0"/>
      <mass value="0.3"/>
      <inertia ixx="0.002" iyy="0.002" izz="0.002" ixy="0" ixz="0" iyz="0"/>
    </inertial>
    <visual>
      <origin xyz="0 0 -0.1" rpy="0 0 0"/>
      <geometry>
        <cylinder radius="0.028" length="0.2"/>
      </geometry>
      <material name="silver">
        <color rgba="0.6 0.65 0.7 1"/>
      </material>
    </visual>
    <collision>
      <origin xyz="0 0 -0.1" rpy="0 0 0"/>
      <geometry>
        <cylinder radius="0.028" length="0.2"/>
      </geometry>
    </collision>
  </link>

  <link name="rr_shank_link">
    <inertial>
      <origin xyz="0 0 -0.1" rpy="0 0 0"/>
      <mass value="0.2"/>
      <inertia ixx="0.001" iyy="0.001" izz="0.001" ixy="0" ixz="0" iyz="0"/>
    </inertial>
    <!-- Upper shank - silver -->
    <visual>
      <origin xyz="0 0 -0.08" rpy="0 0 0"/>
      <geometry>
        <cylinder radius="0.022" length="0.16"/>
      </geometry>
      <material name="silver">
        <color rgba="0.6 0.65 0.7 1"/>
      </material>
    </visual>
    <!-- Foot pad - black rubber-like -->
    <visual>
      <origin xyz="0 0 -0.19" rpy="0 0 0"/>
      <geometry>
        <cylinder radius="0.032" length="0.04"/>
      </geometry>
      <material name="black_rubber">
        <color rgba="0.15 0.15 0.15 1"/>
      </material>
    </visual>
    <collision>
      <origin xyz="0 0 -0.1" rpy="0 0 0"/>
      <geometry>
        <cylinder radius="0.022" length="0.2"/>
      </geometry>
    </collision>
    <collision>
      <origin xyz="0 0 -0.19" rpy="0 0 0"/>
      <geometry>
        <cylinder radius="0.032" length="0.04"/>
      </geometry>
    </collision>
  </link>

  <!-- Joints: hip (roll), thigh (pitch), knee (pitch) for each leg -->

  <!-- Front Left -->
  <joint name="fl_hip_roll_joint" type="revolute">
    <parent link="base_link"/>
    <child link="fl_hip_link"/>
    <origin xyz="0.2 0.1 0.0" rpy="0 0 0"/>
    <axis xyz="1 0 0"/>
    <limit lower="-0.6" upper="0.6" effort="20" velocity="5"/>
  </joint>

  <joint name="fl_hip_pitch_joint" type="revolute">
    <parent link="fl_hip_link"/>
    <child link="fl_thigh_link"/>
    <origin xyz="0 0 0" rpy="0 0 0"/>
    <axis xyz="0 1 0"/>
    <limit lower="-1.0" upper="1.0" effort="20" velocity="5"/>
  </joint>

  <joint name="fl_knee_joint" type="revolute">
    <parent link="fl_thigh_link"/>
    <child link="fl_shank_link"/>
    <origin xyz="0 0 -0.2" rpy="0 0 0"/>
    <axis xyz="0 1 0"/>
    <limit lower="-1.5" upper="0.5" effort="20" velocity="5"/>
  </joint>

  <!-- Front Right -->
  <joint name="fr_hip_roll_joint" type="revolute">
    <parent link="base_link"/>
    <child link="fr_hip_link"/>
    <origin xyz="0.2 -0.1 0.0" rpy="0 0 0"/>
    <axis xyz="1 0 0"/>
    <limit lower="-0.6" upper="0.6" effort="20" velocity="5"/>
  </joint>

  <joint name="fr_hip_pitch_joint" type="revolute">
    <parent link="fr_hip_link"/>
    <child link="fr_thigh_link"/>
    <origin xyz="0 0 0" rpy="0 0 0"/>
    <axis xyz="0 1 0"/>
    <limit lower="-1.0" upper="1.0" effort="20" velocity="5"/>
  </joint>

  <joint name="fr_knee_joint" type="revolute">
    <parent link="fr_thigh_link"/>
    <child link="fr_shank_link"/>
    <origin xyz="0 0 -0.2" rpy="0 0 0"/>
    <axis xyz="0 1 0"/>
    <limit lower="-1.5" upper="0.5" effort="20" velocity="5"/>
  </joint>

  <!-- Rear Left -->
  <joint name="rl_hip_roll_joint" type="revolute">
    <parent link="base_link"/>
    <child link="rl_hip_link"/>
    <origin xyz="-0.2 0.1 0.0" rpy="0 0 0"/>
    <axis xyz="1 0 0"/>
    <limit lower="-0.6" upper="0.6" effort="20" velocity="5"/>
  </joint>

  <joint name="rl_hip_pitch_joint" type="revolute">
    <parent link="rl_hip_link"/>
    <child link="rl_thigh_link"/>
    <origin xyz="0 0 0" rpy="0 0 0"/>
    <axis xyz="0 1 0"/>
    <limit lower="-1.0" upper="1.0" effort="20" velocity="5"/>
  </joint>

  <joint name="rl_knee_joint" type="revolute">
    <parent link="rl_thigh_link"/>
    <child link="rl_shank_link"/>
    <origin xyz="0 0 -0.2" rpy="0 0 0"/>
    <axis xyz="0 1 0"/>
    <limit lower="-1.5" upper="0.5" effort="20" velocity="5"/>
  </joint>

  <!-- Rear Right -->
  <joint name="rr_hip_roll_joint" type="revolute">
    <parent link="base_link"/>
    <child link="rr_hip_link"/>
    <origin xyz="-0.2 -0.1 0.0" rpy="0 0 0"/>
    <axis xyz="1 0 0"/>
    <limit lower="-0.6" upper="0.6" effort="20" velocity="5"/>
  </joint>

  <joint name="rr_hip_pitch_joint" type="revolute">
    <parent link="rr_hip_link"/>
    <child link="rr_thigh_link"/>
    <origin xyz="0 0 0" rpy="0 0 0"/>
    <axis xyz="0 1 0"/>
    <limit lower="-1.0" upper="1.0" effort="20" velocity="5"/>
  </joint>

  <joint name="rr_knee_joint" type="revolute">
    <parent link="rr_thigh_link"/>
    <child link="rr_shank_link"/>
    <origin xyz="0 0 -0.2" rpy="0 0 0"/>
    <axis xyz="0 1 0"/>
    <limit lower="-1.5" upper="0.5" effort="20" velocity="5"/>
  </joint>

</robot>
