<?xml version="1.0"?>
<robot name="go2_like">
  <link name="base_link">
    <inertial>
      <origin xyz="0 0 0" rpy="0 0 0"/>
      <mass value="5.0"/>
      <inertia ixx="0.2" iyy="0.2" izz="0.2" ixy="0" ixz="0" iyz="0"/>
    </inertial>
    <visual>
      <origin xyz="0 0 0" rpy="0 0 0"/>
      <geometry>
        <box size="0.4 0.2 0.1"/>
      </geometry>
      <material name="gray">
        <color rgba="0.6 0.6 0.6 1"/>
      </material>
    </visual>
    <collision>
      <origin xyz="0 0 0" rpy="0 0 0"/>
      <geometry>
        <box size="0.4 0.2 0.1"/>
      </geometry>
    </collision>
  </link>

  <!-- Front Left Leg -->
  <link name="fl_hip_link">
    <inertial>
      <origin xyz="0 0 0" rpy="0 0 0"/>
      <mass value="0.2"/>
      <inertia ixx="0.001" iyy="0.001" izz="0.001" ixy="0" ixz="0" iyz="0"/>
    </inertial>
    <visual>
      <origin xyz="0 0 0" rpy="0 0 0"/>
      <geometry>
        <box size="0.05 0.05 0.05"/>
      </geometry>
    </visual>
    <collision>
      <origin xyz="0 0 0" rpy="0 0 0"/>
      <geometry>
        <box size="0.05 0.05 0.05"/>
      </geometry>
    </collision>
  </link>

  <link name="fl_thigh_link">
    <inertial>
      <origin xyz="0 0 -0.1" rpy="0 0 0"/>
      <mass value="0.3"/>
      <inertia ixx="0.002" iyy="0.002" izz="0.002" ixy="0" ixz="0" iyz="0"/>
    </inertial>
    <visual>
      <origin xyz="0 0 -0.1" rpy="0 0 0"/>
      <geometry>
        <box size="0.05 0.05 0.2"/>
      </geometry>
    </visual>
    <collision>
      <origin xyz="0 0 -0.1" rpy="0 0 0"/>
      <geometry>
        <box size="0.05 0.05 0.2"/>
      </geometry>
    </collision>
  </link>

  <link name="fl_shank_link">
    <inertial>
      <origin xyz="0 0 -0.1" rpy="0 0 0"/>
      <mass value="0.2"/>
      <inertia ixx="0.001" iyy="0.001" izz="0.001" ixy="0" ixz="0" iyz="0"/>
    </inertial>
    <visual>
      <origin xyz="0 0 -0.1" rpy="0 0 0"/>
      <geometry>
        <box size="0.04 0.04 0.2"/>
      </geometry>
    </visual>
    <collision>
      <origin xyz="0 0 -0.1" rpy="0 0 0"/>
      <geometry>
        <box size="0.04 0.04 0.2"/>
      </geometry>
    </collision>
  </link>

  <!-- Front Right Leg -->
  <link name="fr_hip_link">
    <inertial>
      <origin xyz="0 0 0" rpy="0 0 0"/>
      <mass value="0.2"/>
      <inertia ixx="0.001" iyy="0.001" izz="0.001" ixy="0" ixz="0" iyz="0"/>
    </inertial>
    <visual>
      <origin xyz="0 0 0" rpy="0 0 0"/>
      <geometry>
        <box size="0.05 0.05 0.05"/>
      </geometry>
    </visual>
    <collision>
      <origin xyz="0 0 0" rpy="0 0 0"/>
      <geometry>
        <box size="0.05 0.05 0.05"/>
      </geometry>
    </collision>
  </link>

  <link name="fr_thigh_link">
    <inertial>
      <origin xyz="0 0 -0.1" rpy="0 0 0"/>
      <mass value="0.3"/>
      <inertia ixx="0.002" iyy="0.002" izz="0.002" ixy="0" ixz="0" iyz="0"/>
    </inertial>
    <visual>
      <origin xyz="0 0 -0.1" rpy="0 0 0"/>
      <geometry>
        <box size="0.05 0.05 0.2"/>
      </geometry>
    </visual>
    <collision>
      <origin xyz="0 0 -0.1" rpy="0 0 0"/>
      <geometry>
        <box size="0.05 0.05 0.2"/>
      </geometry>
    </collision>
  </link>

  <link name="fr_shank_link">
    <inertial>
      <origin xyz="0 0 -0.1" rpy="0 0 0"/>
      <mass value="0.2"/>
      <inertia ixx="0.001" iyy="0.001" izz="0.001" ixy="0" ixz="0" iyz="0"/>
    </inertial>
    <visual>
      <origin xyz="0 0 -0.1" rpy="0 0 0"/>
      <geometry>
        <box size="0.04 0.04 0.2"/>
      </geometry>
    </visual>
    <collision>
      <origin xyz="0 0 -0.1" rpy="0 0 0"/>
      <geometry>
        <box size="0.04 0.04 0.2"/>
      </geometry>
    </collision>
  </link>

  <!-- Rear Left Leg -->
  <link name="rl_hip_link">
    <inertial>
      <origin xyz="0 0 0" rpy="0 0 0"/>
      <mass value="0.2"/>
      <inertia ixx="0.001" iyy="0.001" izz="0.001" ixy="0" ixz="0" iyz="0"/>
    </inertial>
    <visual>
      <origin xyz="0 0 0" rpy="0 0 0"/>
      <geometry>
        <box size="0.05 0.05 0.05"/>
      </geometry>
    </visual>
    <collision>
      <origin xyz="0 0 0" rpy="0 0 0"/>
      <geometry>
        <box size="0.05 0.05 0.05"/>
      </geometry>
    </collision>
  </link>

  <link name="rl_thigh_link">
    <inertial>
      <origin xyz="0 0 -0.1" rpy="0 0 0"/>
      <mass value="0.3"/>
      <inertia ixx="0.002" iyy="0.002" izz="0.002" ixy="0" ixz="0" iyz="0"/>
    </inertial>
    <visual>
      <origin xyz="0 0 -0.1" rpy="0 0 0"/>
      <geometry>
        <box size="0.05 0.05 0.2"/>
      </geometry>
    </visual>
    <collision>
      <origin xyz="0 0 -0.1" rpy="0 0 0"/>
      <geometry>
        <box size="0.05 0.05 0.2"/>
      </geometry>
    </collision>
  </link>

  <link name="rl_shank_link">
    <inertial>
      <origin xyz="0 0 -0.1" rpy="0 0 0"/>
      <mass value="0.2"/>
      <inertia ixx="0.001" iyy="0.001" izz="0.001" ixy="0" ixz="0" iyz="0"/>
    </inertial>
    <visual>
      <origin xyz="0 0 -0.1" rpy="0 0 0"/>
      <geometry>
        <box size="0.04 0.04 0.2"/>
      </geometry>
    </visual>
    <collision>
      <origin xyz="0 0 -0.1" rpy="0 0 0"/>
      <geometry>
        <box size="0.04 0.04 0.2"/>
      </geometry>
    </collision>
  </link>

  <!-- Rear Right Leg -->
  <link name="rr_hip_link">
    <inertial>
      <origin xyz="0 0 0" rpy="0 0 0"/>
      <mass value="0.2"/>
      <inertia ixx="0.001" iyy="0.001" izz="0.001" ixy="0" ixz="0" iyz="0"/>
    </inertial>
    <visual>
      <origin xyz="0 0 0" rpy="0 0 0"/>
      <geometry>
        <box size="0.05 0.05 0.05"/>
      </geometry>
    </visual>
    <collision>
      <origin xyz="0 0 0" rpy="0 0 0"/>
      <geometry>
        <box size="0.05 0.05 0.05"/>
      </geometry>
    </collision>
  </link>

  <link name="rr_thigh_link">
    <inertial>
      <origin xyz="0 0 -0.1" rpy="0 0 0"/>
      <mass value="0.3"/>
      <inertia ixx="0.002" iyy="0.002" izz="0.002" ixy="0" ixz="0" iyz="0"/>
    </inertial>
    <visual>
      <origin xyz="0 0 -0.1" rpy="0 0 0"/>
      <geometry>
        <box size="0.05 0.05 0.2"/>
      </geometry>
    </visual>
    <collision>
      <origin xyz="0 0 -0.1" rpy="0 0 0"/>
      <geometry>
        <box size="0.05 0.05 0.2"/>
      </geometry>
    </collision>
  </link>

  <link name="rr_shank_link">
    <inertial>
      <origin xyz="0 0 -0.1" rpy="0 0 0"/>
      <mass value="0.2"/>
      <inertia ixx="0.001" iyy="0.001" izz="0.001" ixy="0" ixz="0" iyz="0"/>
    </inertial>
    <visual>
      <origin xyz="0 0 -0.1" rpy="0 0 0"/>
      <geometry>
        <box size="0.04 0.04 0.2"/>
      </geometry>
    </visual>
    <collision>
      <origin xyz="0 0 -0.1" rpy="0 0 0"/>
      <geometry>
        <box size="0.04 0.04 0.2"/>
      </geometry>
    </collision>
  </link>

  <!-- Joints: hip (roll), thigh (pitch), knee (pitch) for each leg -->

  <!-- Front Left -->
  <joint name="fl_hip_roll_joint" type="revolute">
    <parent link="base_link"/>
    <child link="fl_hip_link"/>
    <origin xyz="0.2 0.1 0.0" rpy="0 0 0"/>
    <axis xyz="1 0 0"/>
    <limit lower="-0.6" upper="0.6" effort="20" velocity="5"/>
  </joint>

  <joint name="fl_hip_pitch_joint" type="revolute">
    <parent link="fl_hip_link"/>
    <child link="fl_thigh_link"/>
    <origin xyz="0 0 0" rpy="0 0 0"/>
    <axis xyz="0 1 0"/>
    <limit lower="-1.0" upper="1.0" effort="20" velocity="5"/>
  </joint>

  <joint name="fl_knee_joint" type="revolute">
    <parent link="fl_thigh_link"/>
    <child link="fl_shank_link"/>
    <origin xyz="0 0 -0.2" rpy="0 0 0"/>
    <axis xyz="0 1 0"/>
    <limit lower="-1.5" upper="0.5" effort="20" velocity="5"/>
  </joint>

  <!-- Front Right -->
  <joint name="fr_hip_roll_joint" type="revolute">
    <parent link="base_link"/>
    <child link="fr_hip_link"/>
    <origin xyz="0.2 -0.1 0.0" rpy="0 0 0"/>
    <axis xyz="1 0 0"/>
    <limit lower="-0.6" upper="0.6" effort="20" velocity="5"/>
  </joint>

  <joint name="fr_hip_pitch_joint" type="revolute">
    <parent link="fr_hip_link"/>
    <child link="fr_thigh_link"/>
    <origin xyz="0 0 0" rpy="0 0 0"/>
    <axis xyz="0 1 0"/>
    <limit lower="-1.0" upper="1.0" effort="20" velocity="5"/>
  </joint>

  <joint name="fr_knee_joint" type="revolute">
    <parent link="fr_thigh_link"/>
    <child link="fr_shank_link"/>
    <origin xyz="0 0 -0.2" rpy="0 0 0"/>
    <axis xyz="0 1 0"/>
    <limit lower="-1.5" upper="0.5" effort="20" velocity="5"/>
  </joint>

  <!-- Rear Left -->
  <joint name="rl_hip_roll_joint" type="revolute">
    <parent link="base_link"/>
    <child link="rl_hip_link"/>
    <origin xyz="-0.2 0.1 0.0" rpy="0 0 0"/>
    <axis xyz="1 0 0"/>
    <limit lower="-0.6" upper="0.6" effort="20" velocity="5"/>
  </joint>

  <joint name="rl_hip_pitch_joint" type="revolute">
    <parent link="rl_hip_link"/>
    <child link="rl_thigh_link"/>
    <origin xyz="0 0 0" rpy="0 0 0"/>
    <axis xyz="0 1 0"/>
    <limit lower="-1.0" upper="1.0" effort="20" velocity="5"/>
  </joint>

  <joint name="rl_knee_joint" type="revolute">
    <parent link="rl_thigh_link"/>
    <child link="rl_shank_link"/>
    <origin xyz="0 0 -0.2" rpy="0 0 0"/>
    <axis xyz="0 1 0"/>
    <limit lower="-1.5" upper="0.5" effort="20" velocity="5"/>
  </joint>

  <!-- Rear Right -->
  <joint name="rr_hip_roll_joint" type="revolute">
    <parent link="base_link"/>
    <child link="rr_hip_link"/>
    <origin xyz="-0.2 -0.1 0.0" rpy="0 0 0"/>
    <axis xyz="1 0 0"/>
    <limit lower="-0.6" upper="0.6" effort="20" velocity="5"/>
  </joint>

  <joint name="rr_hip_pitch_joint" type="revolute">
    <parent link="rr_hip_link"/>
    <child link="rr_thigh_link"/>
    <origin xyz="0 0 0" rpy="0 0 0"/>
    <axis xyz="0 1 0"/>
    <limit lower="-1.0" upper="1.0" effort="20" velocity="5"/>
  </joint>

  <joint name="rr_knee_joint" type="revolute">
    <parent link="rr_thigh_link"/>
    <child link="rr_shank_link"/>
    <origin xyz="0 0 -0.2" rpy="0 0 0"/>
    <axis xyz="0 1 0"/>
    <limit lower="-1.5" upper="0.5" effort="20" velocity="5"/>
  </joint>

</robot>
